Traceback (most recent call last):
  File "C:\Users\Spher\OneDrive\Desktop\CS\AI\Image_Caption\main.py", line 78, in <module>
    dataset.sample(model, device_type, starting_text)
  File "C:\Users\Spher\OneDrive\Desktop\CS\AI\Image_Caption\data.py", line 132, in sample
    image, text = self[x]
  File "C:\Users\Spher\OneDrive\Desktop\CS\AI\Image_Caption\data.py", line 67, in __getitem__
    images = self.process_image([s[0] for s in sample])
  File "C:\Users\Spher\OneDrive\Desktop\CS\AI\Image_Caption\data.py", line 88, in process_image
    x[i] = self.transform(images[i])
RuntimeError: The expanded size of the tensor (32) must match the existing size (560) at non-singleton dimension 2.  Target sizes: [3, 32, 32].  Tensor sizes: [3, 315, 560]
Traceback (most recent call last):
  File "C:\Users\Spher\OneDrive\Desktop\CS\AI\Image_Caption\main.py", line 78, in <module>
    dataset.sample(model, device_type, starting_text)
  File "C:\Users\Spher\OneDrive\Desktop\CS\AI\Image_Caption\data.py", line 132, in sample
    image, text = self[x]
  File "C:\Users\Spher\OneDrive\Desktop\CS\AI\Image_Caption\data.py", line 67, in __getitem__
    images = self.process_image([s[0] for s in sample])
  File "C:\Users\Spher\OneDrive\Desktop\CS\AI\Image_Caption\data.py", line 88, in process_image
    x[i] = self.transform(images[i])
RuntimeError: The expanded size of the tensor (32) must match the existing size (560) at non-singleton dimension 2.  Target sizes: [3, 32, 32].  Tensor sizes: [3, 315, 560]