Traceback (most recent call last):
  File "C:\Users\Spher\OneDrive\Desktop\CS\AI\Image_Caption\main.py", line 79, in <module>
    dataset.sample(model, device_type, starting_text, num_tokens=100)
  File "C:\Users\Spher\OneDrive\Desktop\CS\AI\Image_Caption\data.py", line 140, in sample
    print(f"Predicted Caption: {self.decode(new)}")
  File "C:\Users\Spher\OneDrive\Desktop\CS\AI\Image_Caption\data.py", line 59, in <lambda>
    self.decode = lambda l: self.tokenizer.decode(l)
  File "C:\Users\Spher\AppData\Local\Programs\Python\Python39\lib\site-packages\tiktoken\core.py", line 258, in decode
    return self._core_bpe.decode_bytes(tokens).decode("utf-8", errors=errors)
pyo3_runtime.PanicException: no entry found for key
Traceback (most recent call last):
  File "C:\Users\Spher\OneDrive\Desktop\CS\AI\Image_Caption\main.py", line 79, in <module>
    dataset.sample(model, device_type, starting_text, num_tokens=100)
  File "C:\Users\Spher\OneDrive\Desktop\CS\AI\Image_Caption\data.py", line 140, in sample
    print(f"Predicted Caption: {self.decode(new)}")
  File "C:\Users\Spher\OneDrive\Desktop\CS\AI\Image_Caption\data.py", line 59, in <lambda>
    self.decode = lambda l: self.tokenizer.decode(l)
  File "C:\Users\Spher\AppData\Local\Programs\Python\Python39\lib\site-packages\tiktoken\core.py", line 258, in decode
    return self._core_bpe.decode_bytes(tokens).decode("utf-8", errors=errors)
pyo3_runtime.PanicException: no entry found for key